Workbook

Sheet Sheet2
B1: How often variable was rank 1,2,3,4,5
C2: #1 | D2: #2 | E2: #3 | F2: #4 | G2: #5 | H2: total top 5
A3: contraceptive_health_care | B3: Contraceptive requires access to health facility | E3: 1 | H3: =SUM(C3:G3) -> 1
A4: decides_health_care | B4: Involved in decision about own healthcare | E4: 1 | H4: =SUM(C4:G4) -> 1
A5: electricity | B5: Has access to electricity | E5: 1 | H5: =SUM(C5:G5) -> 1
A6: ethnicity_Kalenjin | B6: Ethnicity: Kalenjin | E6: 1 | H6: =SUM(C6:G6) -> 1
A7: ethnicity_Sara_ngambaye_sara_madjin_gaye_mbaye | B7: Ethnicity: Sara ngambaye sara madjin gaye mbaye | G7: 1 | H7: =SUM(C7:G7) -> 1
A8: heard_sti | B8: Heard of STI | F8: 1 | H8: =SUM(C8:G8) -> 1
A9: language_Chichewa | B9: Language: Chichewa | C9: 1 | H9: =SUM(C9:G9) -> 1
A10: language_Krio | B10: Language: Krio | G10: 1 | H10: =SUM(C10:G10) -> 1
A11: language_Runyankole_rukiga | B11: Language: Runyankole rukiga | F11: 1 | H11: =SUM(C11:G11) -> 1
A12: currently_working | B12: *Currently working | D12: 1 | E12: 1 | H12: =SUM(C12:G12) -> 2
A13: language_Yoruba | B13: Language: Yoruba | D13: 2 | H13: =SUM(C13:G13) -> 2
A14: listen_radio | B14: Not at all listens to radio | F14: 2 | H14: =SUM(C14:G14) -> 2
A15: water_time | B15: Time for HH to get to water source | C15: 1 | D15: 1 | H15: =SUM(C15:G15) -> 2
A16: heard_family_planning | B16: Heard of family planning via any media form | C16: 1 | F16: 1 | G16: 1 | H16: =SUM(C16:G16) -> 3
A17: member_women_HH | B17: Number of female HH members | F17: 1 | G17: 2 | H17: =SUM(C17:G17) -> 3
A18: bmi | B18: Body Mass Index | C18: 4 | G18: 1 | H18: =SUM(C18:G18) -> 5
A19: cattle | B19: Number of cattle owned | C19: 1 | D19: 1 | E19: 1 | G19: 3 | H19: =SUM(C19:G19) -> 6
A20: health_card | B20: Health card for child | C20: 3 | D20: 1 | F20: 2 | H20: =SUM(C20:G20) -> 6
A21: member_men_HH | B21: Number of male HH members | F21: 2 | G21: 4 | H21: =SUM(C21:G21) -> 6
A22: tested_HIV | B22: Tested for HIV | D22: 1 | F22: 3 | G22: 3 | H22: =SUM(C22:G22) -> 7
A23: member_child_under_5 | B23: Number of HH members <5 years | E23: 4 | F23: 5 | G23: 3 | H23: =SUM(C23:G23) -> 12
A24: mosquitonets_nr | B24: Number of mosquitonets | D24: 4 | E24: 7 | F24: 5 | G24: 3 | H24: =SUM(C24:G24) -> 19
A25: ideal_nr_children | B25: Ideal number of children | C25: 2 | D25: 10 | E25: 6 | F25: 2 | G25: 2 | H25: =SUM(C25:G25) -> 22
A26: member_all_HH | B26: Number of HH members | C26: 13 | D26: 4 | E26: 7 | F26: 2 | G26: 3 | H26: =SUM(C26:G26) -> 29
C29: =SUM(C3:C28) -> 26 | D29: =SUM(D3:D28) -> 25 | E29: =SUM(E3:E28) -> 30 | F29: =SUM(F3:F28) -> 27 | G29: =SUM(G3:G28) -> 27

Sheet Sheet3
A1: Variable | B1: V1 | C1: V2 | D1: V3 | E1: V4 | F1: V5 | G1: Number | I1: Row Labels | J1: Count of Variable
A2: XGBoost_Benin | B2: member_all_HH | C2: ideal_nr_children | D2: mosquitonets_nr | E2: member_child_under_5 | F2: member_men_HH | G2: 1 | I2: bankaccount | J2: 1
A3: XGBoost_Burkina.Faso | B3: cattle | C3: water_time | D3: member_all_HH | E3: ideal_nr_children | F3: health_card | G3: 1 | I3: contraceptive_health_care | J3: 2
A4: XGBoost_Burundi | B4: ideal_nr_children | C4: member_all_HH | D4: locationBirth | E4: member_men_HH | F4: member_child_under_5 | G4: 1 | I4: decides_health_care | J4: 1
A5: XGBoost_Cameroon | B5: heard_family_planning | C5: tested_HIV | D5: language_Bamoun | E5: soap | F5: terminated_pregnancy | G5: 1 | I5: drinking_water | J5: 1
A6: XGBoost_Chad | B6: member_all_HH | C6: locationBirth | D6: health_card | E6: mosquitonets_nr | F6: member_child_under_5 | G6: 1 | I6: education_no_edu | J6: 1
A7: XGBoost_Cote.dIvoire | B7: health_card | C7: ideal_nr_children | D7: member_all_HH | E7: mosquitonets_nr | F7: drinking_water | G7: 1 | I7: ethnicity_Somali | J7: 1
A8: XGBoost_DRC | B8: water_time | C8: ideal_nr_children | D8: member_all_HH | E8: ethnicity_Bas_kasai_et_kwilu_kwngo | F8: mosquitonets_nr | G8: 1 | I8: health_card | J8: 2
A9: XGBoost_Eswatini | B9: bmi | C9: member_all_HH | D9: ideal_nr_children | E9: member_men_HH | F9: member_child_under_5 | G9: 1 | I9: language_Poular | J9: 1
A10: XGBoost_Ethiopia | B10: bmi | C10: ideal_nr_children | D10: member_all_HH | E10: locationBirth | F10: tested_HIV | G10: 1 | I10: locationBirth | J10: 1
A11: XGBoost_Ghana | B11: ethnicity_Mole_dagbani | C11: member_all_HH | D11: heard_tuberculosis | E11: ethnicity_Akan | F11: health_card | G11: 1 | I11: member_all_HH | J11: 1
A12: XGBoost_Guinea | B12: member_all_HH | C12: heard_sti | D12: mosquitonets_nr | E12: member_child_under_5 | F12: member_men_HH | G12: 1 | I12: member_child_under_5 | J12: 6
A13: XGBoost_Kenya | B13: ethnicity_Kalenjin | C13: bmi | D13: ideal_nr_children | E13: ethnicity_Turkana | F13: ethnicity_Somali | G13: 1 | I13: member_men_HH | J13: 3
... A19: XGBoost_Mauritania | B19: member_all_HH | C19: mosquitonets_nr | D19: member_child_under_5 | E19: locationBirth | F19: language_Poular | G19: 1 | I19: Grand Total | J19: 31
A20: XGBoost_Namibia | B20: member_all_HH | C20: ideal_nr_children | D20: cattle | E20: member_child_under_5 | F20: bankaccount | G20: 1
A21: XGBoost_Niger | B21: health_card | C21: ideal_nr_children | D21: member_all_HH | E21: locationBirth | F21: tested_HIV | G21: 1
A22: XGBoost_Nigeria | B22: ideal_nr_children | C22: member_all_HH | D22: mosquitonets_nr | E22: language_Yoruba | F22: education_no_edu | G22: 1
A23: XGBoost_Republic.of.the.Congo | B23: member_all_HH | C23: ideal_nr_children | D23: locationBirth | E23: mosquitonets_nr | F23: member_child_under_5 | G23: 1
A24: XGBoost_Rwanda | B24: member_all_HH | C24: ideal_nr_children | D24: mosquitonets_nr | E24: cattle | F24: safe_toilet_facility | G24: 1
A25: XGBoost_Senegal | B25: locationBirth | C25: member_all_HH | D25: mosquitonets_nr | E25: tested_HIV | F25: member_child_under_5 | G25: 1
A26: XGBoost_Sierra.Leone | B26: member_all_HH | C26: ideal_nr_children | D26: locationBirth | E26: language_Krio | F26: mosquitonets_nr | G26: 1
A27: XGBoost_Tanzania | B27: bmi | C27: locationBirth | D27: ideal_nr_children | E27: contraceptive_health_care | F27: member_all_HH | G27: 1
A28: XGBoost_The.Gambia | B28: member_all_HH | C28: mosquitonets_nr | D28: member_child_under_5 | E28: member_men_HH | F28: rural | G28: 1
A29: XGBoost_Togo | B29: health_card | C29: locationBirth | D29: tested_HIV | E29: member_all_HH | F29: decides_health_care | G29: 1
A30: XGBoost_Uganda | B30: locationBirth | C30: language_Runyankole_rukiga | D30: ideal_nr_children | E30: member_all_HH | F30: member_child_under_5 | G30: 1
A31: XGBoost_Zambia | B31: ideal_nr_children | C31: member_all_HH | D31: listen_radio | E31: mosquitonets_nr | F31: contraceptive_health_care | G31: 1
A32: XGBoost_Zimbabwe | B32: bmi | C32: member_all_HH | D32: ideal_nr_children | E32: cattle | F32: tested_HIV | G32: 1

Sheet Sheet4
B1: XGBoost_Benin | C1: XGBoost_Burkina.Faso | D1: XGBoost_Burundi | E1: XGBoost_Cameroon | F1: XGBoost_Chad | G1: XGBoost_Cote.dIvoire | H1: XGBoost_DRC | I1: XGBoost_Eswatini | J1: XGBoost_Ethiopia | K1: XGBoost_Ghana | L1: XGBoost_Guinea | M1: XGBoost_Kenya | N1: XGBoost_Lesotho | O1: XGBoost_Liberia | P1: XGBoost_Madagascar | Q1: XGBoost_Malawi | R1: XGBoost_Mali | S1: XGBoost_Mauritania | T1: XGBoost_Namibia | U1: XGBoost_Niger | V1: XGBoost_Nigeria | W1: XGBoost_Republic.of.the.Congo | X1: XGBoost_Rwanda | Y1: XGBoost_Senegal | Z1: XGBoost_Sierra.Leone | AA1: XGBoost_Tanzania | AB1: XGBoost_The.Gambia | AC1: XGBoost_Togo | AD1: XGBoost_Uganda | AE1: XGBoost_Zambia | AF1: XGBoost_Zimbabwe
A2: 1 | B2: member_all_HH | C2: cattle | D2: ideal_nr_children | E2: heard_family_planning | F2: member_all_HH | G2: health_card | H2: water_time | I2: bmi | J2: bmi | K2: ethnicity_Mole_dagbani | L2: member_all_HH | M2: ethnicity_Kalenjin | N2: member_all_HH | O2: locationBirth | P2: heard_family_planning | Q2: language_Chichewa | R2: member_all_HH | S2: member_all_HH | T2: member_all_HH | U2: health_card | V2: ideal_nr_children | W2: member_all_HH | X2: member_all_HH | Y2: locationBirth | Z2: member_all_HH | AA2: bmi | AB2: member_all_HH | AC2: health_card | AD2: locationBirth | AE2: ideal_nr_children | AF2: bmi
A3: 2 | B3: ideal_nr_children | C3: water_time | D3: member_all_HH | E3: tested_HIV | F3: locationBirth | G3: ideal_nr_children | H3: ideal_nr_children | I3: member_all_HH | J3: ideal_nr_children | K3: member_all_HH | L3: heard_sti | M3: bmi | N3: cattle | O3: member_all_HH | P3: tested_HIV | Q3: currently_working | R3: mosquitonets_nr | S3: mosquitonets_nr | T3: ideal_nr_children | U3: ideal_nr_children | V3: member_all_HH | W3: ideal_nr_children | X3: ideal_nr_children | Y3: member_all_HH | Z3: ideal_nr_children | AA3: locationBirth | AB3: mosquitonets_nr | AC3: locationBirth | AD3: language_Runyankole_rukiga | AE3: member_all_HH | AF3: member_all_HH
A4: 3 | B4: mosquitonets_nr | C4: member_all_HH | D4: locationBirth | E4: language_Bamoun | F4: health_card | G4: member_all_HH | H4: member_all_HH | I4: ideal_nr_children | J4: member_all_HH | K4: heard_tuberculosis | L4: mosquitonets_nr | M4: ideal_nr_children | N4: ideal_nr_children | O4: currently_working | P4: locationBirth | Q4: member_all_HH | R4: tested_HIV | S4: member_child_under_5 | T4: cattle | U4: member_all_HH | V4: mosquitonets_nr | W4: locationBirth | X4: mosquitonets_nr | Y4: mosquitonets_nr | Z4: locationBirth | AA4: ideal_nr_children | AB4: member_child_under_5 | AC4: tested_HIV | AD4: ideal_nr_children | AE4: listen_radio | AF4: ideal_nr_children
A5: 4 | B5: member_child_under_5 | C5: ideal_nr_children | D5: member_men_HH | E5: soap | F5: mosquitonets_nr | G5: mosquitonets_nr | H5: ethnicity_Bas_kasai_et_kwilu_kwngo | I5: member_men_HH | J5: locationBirth | K5: ethnicity_Akan | L5: member_child_under_5 | M5: ethnicity_Turkana | N5: member_child_under_5 | O5: ideal_nr_children | P5: listen_radio | Q5: ideal_nr_children | R5: heard_family_planning | S5: locationBirth | T5: member_child_under_5 | U5: locationBirth | V5: language_Yoruba | W5: mosquitonets_nr | X5: cattle | Y5: tested_HIV | Z5: language_Krio | AA5: contraceptive_health_care | AB5: member_men_HH | AC5: member_all_HH | AD5: member_all_HH | AE5: mosquitonets_nr | AF5: cattle
A6: 5 | B6: member_men_HH | C6: health_card | D6: member_child_under_5 | E6: terminated_pregnancy | F6: member_child_under_5 | G6: drinking_water | H6: mosquitonets_nr | I6: member_child_under_5 | J6: tested_HIV | K6: health_card | L6: member_men_HH | M6: ethnicity_Somali | N6: member_men_HH | O6: contraceptive_health_care | P6: mosquitonets_nr | Q6: mosquitonets_nr | R6: locationBirth | S6: language_Poular | T6: bankaccount | U6: tested_HIV | V6: education_no_edu | W6: member_child_under_5 | X6: safe_toilet_facility | Y6: member_child_under_5 | Z6: mosquitonets_nr | AA6: member_all_HH | AB6: rural | AC6: decides_health_care | AD6: member_child_under_5 | AE6: contraceptive_health_care | AF6: tested_HIV
B8: XGBoost_Benin | C8: XGBoost_Burkina.Faso | D8: XGBoost_Burundi | E8: XGBoost_Cameroon | F8: XGBoost_Chad | G8: XGBoost_Cote.dIvoire | H8: XGBoost_DRC | I8: XGBoost_Eswatini | J8: XGBoost_Ethiopia | K8: XGBoost_Ghana | L8: XGBoost_Guinea | M8: XGBoost_Kenya | N8: XGBoost_Lesotho | O8: XGBoost_Liberia | P8: XGBoost_Madagascar | Q8: XGBoost_Malawi | R8: XGBoost_Mali | S8: XGBoost_Mauritania | T8: XGBoost_Namibia | U8: XGBoost_Niger | V8: XGBoost_Nigeria | W8: XGBoost_Republic.of.the.Congo | X8: XGBoost_Rwanda | Y8: XGBoost_Senegal | Z8: XGBoost_Sierra.Leone | AA8: XGBoost_Tanzania | AB8: XGBoost_The.Gambia | AC8: XGBoost_Togo | AD8: XGBoost_Uganda | AE8: XGBoost_Zambia | AF8: XGBoost_Zimbabwe
A9: 1 | B9: 100 | C9: 100 | D9: 100 | E9: 100 | F9: 100 | G9: 100 | H9: 100 | I9: 100 | J9: 100 | K9: 100 | L9: 100 | M9: 100 | N9: 100 | O9: 100 | P9: 100 | Q9: 100 | R9: 100 | S9: 100 | T9: 100 | U9: 100 | V9: 100 | W9: 100 | X9: 100 | Y9: 100 | Z9: 100 | AA9: 100 | AB9: 100 | AC9: 100 | AD9: 100 | AE9: 100 | AF9: 100
A10: 2 | B10: 90.569933 | C10: 70.341727 | D10: 96.250029 | E10: 72.825394 | F10: 67.680519 | G10: 57.524785 | H10: 75.32017 | I10: 52.070679 | J10: 38.941323 | K10: 74.951007 | L10: 56.954031 | M10: 85.68705 | N10: 76.633308 | O10: 15.634833 | P10: 66.641776 | Q10: 57.42469 | R10: 78.746135 | S10: 50.534565 | T10: 91.980699 | U10: 32.691861 | V10: 96.513866 | W10: 90.384096 | X10: 85.118473 | Y10: 30.428377 | Z10: 92.687329 | AA10: 83.198833 | AB10: 62.888646 | AC10: 78.480025 | AD10: 94.316911 | AE10: 85.08502 | AF10: 37.879216
A11: 3 | B11: 64.505939 | C11: 65.846687 | D11: 82.571127 | E11: 69.078418 | F11: 61.748974 | G11: 55.87987 | H11: 66.237475 | I11: 38.423309 | J11: 33.146062 | K11: 72.343304 | L11: 55.43391 | M11: 77.556461 | N11: 69.971886 | O11: 14.982779 | P11: 50.652644 | Q11: 56.167001 | R11: 66.742747 | S11: 44.765115 | T11: 80.255033 | U11: 28.574549 | V11: 57.306486 | W11: 78.283319 | X11: 51.05968 | Y11: 25.158483 | Z11: 80.073149 | AA11: 68.327207 | AB11: 60.056537 | AC11: 78.128447 | AD11: 77.338985 | AE11: 64.333644 | AF11: 34.302059
A12: 4 | B12: 53.774078 | C12: 51.561413 | D12: 41.025246 | E12: 66.941503 | F12: 55.496396 | G12: 29.799902 | H12: 44.734249 | I12: 25.838406 | J12: 24.696425 | K12: 64.054745 | L12: 49.005963 | M12: 48.910605 | N12: 38.542023 | O12: 13.428386 | P12: 48.150415 | Q12: 39.842201 | R12: 61.626118 | S12: 41.895143 | T12: 48.710529 | U12: 23.481494 | V12: 56.757589 | W12: 54.177675 | X12: 45.096245 | Y12: 14.365856 | Z12: 68.51006 | AA12: 59.219782 | AB12: 50.106905 | AC12: 51.649335 | AD12: 59.748787 | AE12: 62.938312 | AF12: 26.763817
A13: 5 | B13: 39.951596 | C13: 49.629297 | D13: 40.000665 | E13: 56.552526 | F13: 45.849359 | G13: 26.934847 | H13: 37.468645 | I13: 22.849243 | J13: 24.227308 | K13: 61.932523 | L13: 48.381193 | M13: 31.322639 | N13: 35.886353 | O13: 13.288134 | P13: 35.481449 | Q13: 36.287856 | R13: 51.840777 | S13: 39.913242 | T13: 48.683761 | U13: 19.275463 | V13: 50.792993 | W13: 48.738149 | X13: 45.076424 | Y13: 13.918048 | Z13: 61.74795 | AA13: 47.618314 | AB13: 48.44381 | AC13: 50.400775 | AD13: 54.429581 | AE13: 51.125061 | AF13: 22.973684
A16: =A8 -> 0 | B16: XGBoost_Benin | C16: XGBoost_Burkina.Faso | D16: XGBoost_Burundi | E16: XGBoost_Cameroon | F16: XGBoost_Chad | G16: XGBoost_Cote.dIvoire | H16: XGBoost_DRC | I16: XGBoost_Eswatini | J16: XGBoost_Ethiopia | K16: XGBoost_Ghana | L16: XGBoost_Guinea | M16: XGBoost_Kenya | N16: XGBoost_Lesotho | O16: XGBoost_Liberia | P16: XGBoost_Madagascar | Q16: XGBoost_Malawi | R16: XGBoost_Mali | S16: XGBoost_Mauritania | T16: XGBoost_Namibia | U16: XGBoost_Niger | V16: XGBoost_Nigeria | W16: XGBoost_Republic.of.the.Congo | X16: XGBoost_Rwanda | Y16: XGBoost_Senegal | Z16: XGBoost_Sierra.Leone | AA16: XGBoost_Tanzania | AB16: XGBoost_The.Gambia | AC16: XGBoost_Togo | AD16: XGBoost_Uganda | AE16: XGBoost_Zambia | AF16: XGBoost_Zimbabwe
A17: =A2 -> 1 | B17: =VLOOKUP(B2,Sheet2!$A$2:$B$62,2,FALSE) -> Number of HH members | C17: =VLOOKUP(C2,Sheet2!$A$2:$B$62,2,FALSE) -> Number of cattle owned | D17: =VLOOKUP(D2,Sheet2!$A$2:$B$62,2,FALSE) -> Ideal number of children | E17: =VLOOKUP(E2,Sheet2!$A$2:$B$62,2,FALSE) -> Heard of family planning via any media form | F17: =VLOOKUP(F2,Sheet2!$A$2:$B$62,2,FALSE) -> Number of HH members | G17: =VLOOKUP(G2,Sheet2!$A$2:$B$62,2,FALSE) -> Health card for child | H17: =VLOOKUP(H2,Sheet2!$A$2:$B$62,2,FALSE) -> Time for HH to get to water source | I17: =VLOOKUP(I2,Sheet2!$A$2:$B$62,2,FALSE) -> Body Mass Index | ... AF17: =VLOOKUP(AF2,Sheet2!$A$2:$B$62,2,FALSE) -> Body Mass Index
A18: =A9 -> 1 | B18: =B9 -> 100 | C18: =C9 -> 100 | D18: =D9 -> 100 | E18: =E9 -> 100 | F18: =F9 -> 100 | G18: =G9 -> 100 | H18: =H9 -> 100 | ... AF18: =AF9 -> 100
A19: =A3 -> 2 | B19: =VLOOKUP(B3,Sheet2!$A$2:$B$62,2,FALSE) -> Ideal number of children | C19: =VLOOKUP(C3,Sheet2!$A$2:$B$62,2,FALSE) -> Time for HH to get to water source | D19: =VLOOKUP(D3,Sheet2!$A$2:$B$62,2,FALSE) -> Number of HH members | E19: =VLOOKUP(E3,Sheet2!$A$2:$B$62,2,FALSE) -> Tested for HIV | F19: =VLOOKUP(F3,Sheet2!$A$2:$B$62,2,FALSE) -> #N/A | G19: =VLOOKUP(G3,Sheet2!$A$2:$B$62,2,FALSE) -> Ideal number of children | H19: =VLOOKUP(H3,Sheet2!$A$2:$B$62,2,FALSE) -> Ideal number of children | I19: =VLOOKUP(I3,Sheet2!$A$2:$B$62,2,FALSE) -> Number of HH members | ... AF19: =VLOOKUP(AF3,Sheet2!$A$2:$B$62,2,FALSE) -> Number of HH members
A20: =A10 -> 2 | B20: =B10 -> 90.569933 | C20: =C10 -> 70.341727 | D20: =D10 -> 96.250029 | E20: =E10 -> 72.825394 | F20: =F10 -> 67.680519 | G20: =G10 -> 57.524785 | H20: =H10 -> 75.32017 | ... AF20: =AF10 -> 37.879216
A21: =A4 -> 3 | B21: =VLOOKUP(B4,Sheet2!$A$2:$B$62,2,FALSE) -> Number of mosquitonets | C21: =VLOOKUP(C4,Sheet2!$A$2:$B$62,2,FALSE) -> Number of HH members | D21: =VLOOKUP(D4,Sheet2!$A$2:$B$62,2,FALSE) -> #N/A | E21: =VLOOKUP(E4,Sheet2!$A$2:$B$62,2,FALSE) -> #N/A | F21: =VLOOKUP(F4,Sheet2!$A$2:$B$62,2,FALSE) -> Health card for child | G21: =VLOOKUP(G4,Sheet2!$A$2:$B$62,2,FALSE) -> Number of HH members | H21: =VLOOKUP(H4,Sheet2!$A$2:$B$62,2,FALSE) -> Number of HH members | I21: =VLOOKUP(I4,Sheet2!$A$2:$B$62,2,FALSE) -> Ideal number of children | ... AF21: =VLOOKUP(AF4,Sheet2!$A$2:$B$62,2,FALSE) -> Ideal number of children
A22: =A11 -> 3 | B22: =B11 -> 64.505939 | C22: =C11 -> 65.846687 | D22: =D11 -> 82.571127 | E22: =E11 -> 69.078418 | F22: =F11 -> 61.748974 | G22: =G11 -> 55.87987 | H22: =H11 -> 66.237475 | ... AF22: =AF11 -> 34.302059
A23: =A5 -> 4 | B23: =VLOOKUP(B5,Sheet2!$A$2:$B$62,2,FALSE) -> Number of HH members <5 years | C23: =VLOOKUP(C5,Sheet2!$A$2:$B$62,2,FALSE) -> Ideal number of children | D23: =VLOOKUP(D5,Sheet2!$A$2:$B$62,2,FALSE) -> Number of male HH members | E23: =VLOOKUP(E5,Sheet2!$A$2:$B$62,2,FALSE) -> #N/A | F23: =VLOOKUP(F5,Sheet2!$A$2:$B$62,2,FALSE) -> Number of mosquitonets | G23: =VLOOKUP(G5,Sheet2!$A$2:$B$62,2,FALSE) -> Number of mosquitonets | H23: =VLOOKUP(H5,Sheet2!$A$2:$B$62,2,FALSE) -> #N/A | I23: =VLOOKUP(I5,Sheet2!$A$2:$B$62,2,FALSE) -> Number of male HH members | ... AF23: =VLOOKUP(AF5,Sheet2!$A$2:$B$62,2,FALSE) -> Number of cattle owned
A24: =A12 -> 4 | B24: =B12 -> 53.774078 | C24: =C12 -> 51.561413 | D24: =D12 -> 41.025246 | E24: =E12 -> 66.941503 | F24: =F12 -> 55.496396 | G24: =G12 -> 29.799902 | H24: =H12 -> 44.734249 | ... AF24: =AF12 -> 26.763817
A25: =A6 -> 5 | B25: =VLOOKUP(B6,Sheet2!$A$2:$B$62,2,FALSE) -> Number of male HH members | C25: =VLOOKUP(C6,Sheet2!$A$2:$B$62,2,FALSE) -> Health card for child | D25: =VLOOKUP(D6,Sheet2!$A$2:$B$62,2,FALSE) -> Number of HH members <5 years | E25: =VLOOKUP(E6,Sheet2!$A$2:$B$62,2,FALSE) -> #N/A | F25: =VLOOKUP(F6,Sheet2!$A$2:$B$62,2,FALSE) -> Number of HH members <5 years | G25: =VLOOKUP(G6,Sheet2!$A$2:$B$62,2,FALSE) -> #N/A | H25: =VLOOKUP(H6,Sheet2!$A$2:$B$62,2,FALSE) -> Number of mosquitonets | I25: =VLOOKUP(I6,Sheet2!$A$2:$B$62,2,FALSE) -> Number of HH members <5 years | ... AF25: =VLOOKUP(AF6,Sheet2!$A$2:$B$62,2,FALSE) -> Tested for HIV
A26: =A13 -> 5 | B26: =B13 -> 39.951596 | C26: =C13 -> 49.629297 | D26: =D13 -> 40.000665 | E26: =E13 -> 56.552526 | F26: =F13 -> 45.849359 | G26: =G13 -> 26.934847 | H26: =H13 -> 37.468645 | ... AF26: =AF13 -> 22.973684
A29: 0 | B29: XGBoost_Benin | C29: XGBoost_Burkina.Faso | D29: XGBoost_Burundi | E29: XGBoost_Cameroon | F29: XGBoost_Chad | G29: XGBoost_Cote.dIvoire | H29: XGBoost_DRC | I29: XGBoost_Eswatini | J29: XGBoost_Ethiopia | K29: XGBoost_Ghana | L29: XGBoost_Guinea | M29: XGBoost_Kenya | N29: XGBoost_Lesotho | O29: XGBoost_Liberia | P29: XGBoost_Madagascar | Q29: XGBoost_Malawi | R29: XGBoost_Mali | S29: XGBoost_Mauritania | T29: XGBoost_Namibia | U29: XGBoost_Niger | V29: XGBoost_Nigeria | W29: XGBoost_Republic.of.the.Congo | X29: XGBoost_Rwanda | Y29: XGBoost_Senegal | Z29: XGBoost_Sierra.Leone | AA29: XGBoost_Tanzania | AB29: XGBoost_The.Gambia | AC29: XGBoost_Togo | AD29: XGBoost_Uganda | AE29: XGBoost_Zambia | AF29: XGBoost_Zimbabwe
A30: 1 | B30: Number of HH members | C30: Number of cattle owned | D30: Ideal number of children | E30: Heard of family planning via any media form | F30: Number of HH members | G30: Health card for child | H30: Time for HH to get to water source | I30: Body Mass Index | J30: Body Mass Index | K30: Ethnicity: Mole dagbani | L30: Number of HH members | M30: Ethnicity: Kalenjin | N30: Number of HH members | O30: Health facility-based birth | P30: Heard of family planning via any media form | Q30: Language: Chichewa | R30: Number of HH members | S30: Number of HH members | T30: Number of HH members | U30: Health card for child | V30: Ideal number of children | W30: Number of HH members | X30: Number of HH members | Y30: Health facility-based birth | Z30: Number of HH members | AA30: Body Mass Index | AB30: Number of HH members | AC30: Health card for child | AD30: Health facility-based birth | AE30: Ideal number of children | AF30: Body Mass Index
A31: 1 | B31: 100 | C31: 100 | D31: 100 | E31: 100 | F31: 100 | G31: 100 | H31: 100 | I31: 100 | J31: 100 | K31: 100 | L31: 100 | M31: 100 | N31: 100 | O31: 100 | P31: 100 | Q31: 100 | R31: 100 | S31: 100 | T31: 100 | U31: 100 | V31: 100 | W31: 100 | X31: 100 | Y31: 100 | Z31: 100 | AA31: 100 | AB31: 100 | AC31: 100 | AD31: 100 | AE31: 100 | AF31: 100
A32: 2 | B32: Ideal number of children | C32: Time for HH to get to water source | D32: Number of HH members | E32: Tested for HIV | F32: Health facility-based birth | G32: Ideal number of children | H32: Ideal number of children | I32: Number of HH members | J32: Ideal number of children | K32: Number of HH members | L32: Heard of STI | M32: Body Mass Index | N32: Number of cattle owned | O32: Number of HH members | P32: Tested for HIV | Q32: *Currently working | R32: Number of mosquitonets | S32: Number of mosquitonets | T32: Ideal number of children | U32: Ideal number of children | V32: Number of HH members | W32: Ideal number of children | X32: Ideal number of children | Y32: Number of HH members | Z32: Ideal number of children | AA32: Health facility-based birth | AB32: Number of mosquitonets | AC32: Health facility-based birth | AD32: Language: Runyankole rukiga | AE32: Number of HH members | AF32: Number of HH members
A33: 2 | B33: 90.569933 | C33: 70.341727 | D33: 96.250029 | E33: 72.825394 | F33: 67.680519 | G33: 57.524785 | H33: 75.32017 | I33: 52.070679 | J33: 38.941323 | K33: 74.951007 | L33: 56.954031 | M33: 85.68705 | N33: 76.633308 | O33: 15.634833 | P33: 66.641776 | Q33: 57.42469 | R33: 78.746135 | S33: 50.534565 | T33: 91.980699 | U33: 32.691861 | V33: 96.513866 | W33: 90.384096 | X33: 85.118473 | Y33: 30.428377 | Z33: 92.687329 | AA33: 83.198833 | AB33: 62.888646 | AC33: 78.480025 | AD33: 94.316911 | AE33: 85.08502 | AF33: 37.879216
A34: 3 | B34: Number of mosquitonets | C34: Number of HH members | D34: Health facility-based birth | E34: Language: Bamoun | F34: Health card for child | G34: Number of HH members | H34: Number of HH members | I34: Ideal number of children | J34: Number of HH members | K34: Heard of tuberculosis | L34: Number of mosquitonets | M34: Ideal number of children | N34: Ideal number of children | O34: *Currently working | P34: Health facility-based birth | Q34: Number of HH members | R34: Tested for HIV | S34: Number of HH members <5 years | T34: Number of cattle owned | U34: Number of HH members | V34: Number of mosquitonets | W34: Health facility-based birth | X34: Number of mosquitonets | Y34: Number of mosquitonets | Z34: Health facility-based birth | AA34: Ideal number of children | AB34: Number of HH members <5 years | AC34: Tested for HIV | AD34: Ideal number of children | AE34: Not at all listens to radio | AF34: Ideal number of children
A35: 3 | B35: 64.505939 | C35: 65.846687 | D35: 82.571127 | E35: 69.078418 | F35: 61.748974 | G35: 55.87987 | H35: 66.237475 | I35: 38.423309 | J35: 33.146062 | K35: 72.343304 | L35: 55.43391 | M35: 77.556461 | N35: 69.971886 | O35: 14.982779 | P35: 50.652644 | Q35: 56.167001 | R35: 66.742747 | S35: 44.765115 | T35: 80.255033 | U35: 28.574549 | V35: 57.306486 | W35: 78.283319 | X35: 51.05968 | Y35: 25.158483 | Z35: 80.073149 | AA35: 68.327207 | AB35: 60.056537 | AC35: 78.128447 | AD35: 77.338985 | AE35: 64.333644 | AF35: 34.302059
A36: 4 | B36: Number of HH members <5 years | C36: Ideal number of children | D36: Number of male HH members | E36: Soap present at place for hand washing | F36: Number of mosquitonets | G36: Number of mosquitonets | H36: Ethnicity: Bas kasai and kwilu kwngo | I36: Number of male HH members | J36: Health facility-based birth | K36: Ethnicity: Akan | L36: Number of HH members <5 years | M36: Ethnicity: Turkana | N36: Number of HH members <5 years | O36: Ideal number of children | P36: Not at all listens to radio | Q36: Ideal number of children | R36: Heard of family planning via any media form | S36: Health facility-based birth | T36: Number of HH members <5 years | U36: Health facility-based birth | V36: Language: Yoruba | W36: Number of mosquitonets | X36: Number of cattle owned | Y36: Tested for HIV | Z36: Language: Krio | AA36: Contraceptive requires access to health facility | AB36: Number of male HH members | AC36: Number of HH members | AD36: Number of HH members | AE36: Number of mosquitonets | AF36: Number of cattle owned
A37: 4 | B37: 53.774078 | C37: 51.561413 | D37: 41.025246 | E37: 66.941503 | F37: 55.496396 | G37: 29.799902 | H37: 44.734249 | I37: 25.838406 | J37: 24.696425 | K37: 64.054745 | L37: 49.005963 | M37: 48.910605 | N37: 38.542023 | O37: 13.428386 | P37: 48.150415 | Q37: 39.842201 | R37: 61.626118 | S37: 41.895143 | T37: 48.710529 | U37: 23.481494 | V37: 56.757589 | W37: 54.177675 | X37: 45.096245 | Y37: 14.365856 | Z37: 68.51006 | AA37: 59.219782 | AB37: 50.106905 | AC37: 51.649335 | AD37: 59.748787 | AE37: 62.938312 | AF37: 26.763817
A38: 5 | B38: Number of male HH members | C38: Health card for child | D38: Number of HH members <5 years | E38: Ever had a terminated pregnancy | F38: Number of HH members <5 years | G38: Has access to source of drinking water | H38: Number of mosquitonets | I38: Number of HH members <5 years | J38: Tested for HIV | K38: Health card for child | L38: Number of male HH members | M38: Ethnicity: Somali | N38: Number of male HH members | O38: Contraceptive requires access to health facility | P38: Number of mosquitonets | Q38: Number of mosquitonets | R38: Health facility-based birth | S38: Language: Poular | T38: Has bankaccount | U38: Tested for HIV | V38: *No education level attained | W38: Number of HH members <5 years | X38: Safe toilet facility | Y38: Number of HH members <5 years | Z38: Number of mosquitonets | AA38: Number of HH members | AB38: *Rural place of residence | AC38: Involved in decision about own healthcare | AD38: Number of HH members <5 years | AE38: Contraceptive requires access to health facility | AF38: Tested for HIV
A39: 5 | B39: 39.951596 | C39: 49.629297 | D39: 40.000665 | E39: 56.552526 | F39: 45.849359 | G39: 26.934847 | H39: 37.468645 | I39: 22.849243 | J39: 24.227308 | K39: 61.932523 | L39: 48.381193 | M39: 31.322639 | N39: 35.886353 | O39: 13.288134 | P39: 35.481449 | Q39: 36.287856 | R39: 51.840777 | S39: 39.913242 | T39: 48.683761 | U39: 19.275463 | V39: 50.792993 | W39: 48.738149 | X39: 45.076424 | Y39: 13.918048 | Z39: 61.74795 | AA39: 47.618314 | AB39: 48.44381 | AC39: 50.400775 | AD39: 54.429581 | AE39: 51.125061 | AF39: 22.973684
C41: Top #1 | E41: Top #2 | G41: Top #3 | I41: Top #4 | K41: Top #5
C42: Predictor | D42: Variable Importance | E42: Predictor | F42: Variable Importance | G42: Predictor | H42: Variable Importance | I42: Predictor | J42: Variable Importance | K42: Predictor | L42: Variable Importance
A43: XGBoost_Benin | B43: Benin | C43: Number of HH members | D43: 100 | E43: Ideal number of children | F43: 90.569933 | G43: Number of mosquitonets | H43: 64.505939 | I43: Number of HH members <5 years | J43: 53.774078 | K43: Number of male HH members | L43: 39.951596
A44: XGBoost_Burkina.Faso | B44: Burkina.Faso | C44: Number of cattle owned | D44: 100 | E44: Time for HH to get to water source | F44: 70.341727 | G44: Number of HH members | H44: 65.846687 | I44: Ideal number of children | J44: 51.561413 | K44: Health card for child | L44: 49.629297
A45: XGBoost_Burundi | B45: Burundi | C45: Ideal number of children | D45: 100 | E45: Number of HH members | F45: 96.250029 | G45: Health facility-based birth | H45: 82.571127 | I45: Number of male HH members | J45: 41.025246 | K45: Number of HH members <5 years | L45: 40.000665
A46: XGBoost_Cameroon | B46: Cameroon | C46: Heard of family planning via any media form | D46: 100 | E46: Tested for HIV | F46: 72.825394 | G46: Language: Bamoun | H46: 69.078418 | I46: Soap present at place for hand washing | J46: 66.941503 | K46: Ever had a terminated pregnancy | L46: 56.552526
...
